Workbook

Sheet Sheet1
A1: County | B1: FIPS | C1: School ID
A2: Appling County | B2: 13001 | C2: =_xlfn.XLOOKUP(A2,Sheet2!B:B,Sheet2!A:A) -> 601
A3: Atkinson County | B3: 13003 | C3: =_xlfn.XLOOKUP(A3,Sheet2!B:B,Sheet2!A:A) -> 602
A4: Bacon County | B4: 13005 | C4: =_xlfn.XLOOKUP(A4,Sheet2!B:B,Sheet2!A:A) -> 603
A5: Baker County | B5: 13007 | C5: =_xlfn.XLOOKUP(A5,Sheet2!B:B,Sheet2!A:A) -> 604
A6: Baldwin County | B6: 13009 | C6: =_xlfn.XLOOKUP(A6,Sheet2!B:B,Sheet2!A:A) -> 605
A7: Banks County | B7: 13011 | C7: =_xlfn.XLOOKUP(A7,Sheet2!B:B,Sheet2!A:A) -> 606
A8: Barrow County | B8: 13013 | C8: =_xlfn.XLOOKUP(A8,Sheet2!B:B,Sheet2!A:A) -> 607
A9: Bartow County | B9: 13015 | C9: =_xlfn.XLOOKUP(A9,Sheet2!B:B,Sheet2!A:A) -> 608
A10: Ben Hill County | B10: 13015 | C10: =_xlfn.XLOOKUP(A10,Sheet2!B:B,Sheet2!A:A) -> 609
A11: Berrien County | B11: 13017 | C11: =_xlfn.XLOOKUP(A11,Sheet2!B:B,Sheet2!A:A) -> 610
A12: Bibb County | B12: 13019 | C12: =_xlfn.XLOOKUP(A12,Sheet2!B:B,Sheet2!A:A) -> 611
A13: Bleckley County | B13: 13021 | C13: =_xlfn.XLOOKUP(A13,Sheet2!B:B,Sheet2!A:A) -> 612
... A25: Charlton County | B25: 13037 | C25: =_xlfn.XLOOKUP(A25,Sheet2!B:B,Sheet2!A:A) -> 624
A26: Chatham County | B26: 13037 | C26: N/A
A27: Chattahoochee County | B27: 13039 | C27: =_xlfn.XLOOKUP(A27,Sheet2!B:B,Sheet2!A:A) -> 626
A28: Chattooga County | B28: 13043 | C28: =_xlfn.XLOOKUP(A28,Sheet2!B:B,Sheet2!A:A) -> 627
A29: Cherokee County | B29: 13045 | C29: =_xlfn.XLOOKUP(A29,Sheet2!B:B,Sheet2!A:A) -> 628
A30: Clarke County | B30: 13045 | C30: =_xlfn.XLOOKUP(A30,Sheet2!B:B,Sheet2!A:A) -> 629
A31: Clay County | B31: 13047 | C31: =_xlfn.XLOOKUP(A31,Sheet2!B:B,Sheet2!A:A) -> 630
A32: Clayton County | B32: 13049 | C32: =_xlfn.XLOOKUP(A32,Sheet2!B:B,Sheet2!A:A) -> 631
A33: Clinch County | B33: 13051 | C33: =_xlfn.XLOOKUP(A33,Sheet2!B:B,Sheet2!A:A) -> 632
A34: Cobb County | B34: 13053 | C34: =_xlfn.XLOOKUP(A34,Sheet2!B:B,Sheet2!A:A) -> 633
A35: Coffee County | B35: 13055 | C35: =_xlfn.XLOOKUP(A35,Sheet2!B:B,Sheet2!A:A) -> 634
A36: Colquitt County | B36: 13055 | C36: =_xlfn.XLOOKUP(A36,Sheet2!B:B,Sheet2!A:A) -> 635
A37: Columbia County | B37: 13057 | C37: =_xlfn.XLOOKUP(A37,Sheet2!B:B,Sheet2!A:A) -> 636
A38: Cook County | B38: 13057 | C38: =_xlfn.XLOOKUP(A38,Sheet2!B:B,Sheet2!A:A) -> 637
... A126: Seminole County | B126: 13127 | C126: =_xlfn.XLOOKUP(A126,Sheet2!B:B,Sheet2!A:A) -> 725
A127: Spalding County | B127: 13129 | C127: N/A
A128: Stephens County | B128: 13129 | C128: =_xlfn.XLOOKUP(A128,Sheet2!B:B,Sheet2!A:A) -> 727
A129: Stewart County | B129: 13131 | C129: =_xlfn.XLOOKUP(A129,Sheet2!B:B,Sheet2!A:A) -> 728
A130: Sumter County | B130: 13133 | C130: =_xlfn.XLOOKUP(A130,Sheet2!B:B,Sheet2!A:A) -> 729
A131: Talbot County | B131: 13135 | C131: =_xlfn.XLOOKUP(A131,Sheet2!B:B,Sheet2!A:A) -> 730
A132: Taliaferro County | B132: 13135 | C132: =_xlfn.XLOOKUP(A132,Sheet2!B:B,Sheet2!A:A) -> 731
A133: Tattnall County | B133: 13135 | C133: =_xlfn.XLOOKUP(A133,Sheet2!B:B,Sheet2!A:A) -> 732
A134: Taylor County | B134: 13135 | C134: =_xlfn.XLOOKUP(A134,Sheet2!B:B,Sheet2!A:A) -> 733
A135: Telfair County | B135: 13135 | C135: =_xlfn.XLOOKUP(A135,Sheet2!B:B,Sheet2!A:A) -> 734
A136: Terrell County | B136: 13135 | C136: =_xlfn.XLOOKUP(A136,Sheet2!B:B,Sheet2!A:A) -> 735
A137: Thomas County | B137: 13137 | C137: =_xlfn.XLOOKUP(A137,Sheet2!B:B,Sheet2!A:A) -> 736
A138: Tift County | B138: 13139 | C138: =_xlfn.XLOOKUP(A138,Sheet2!B:B,Sheet2!A:A) -> 737
...

Sheet Sheet2
A1: 601 | B1: Appling County
A2: 602 | B2: Atkinson County
A3: 603 | B3: Bacon County
A4: 604 | B4: Baker County
A5: 605 | B5: Baldwin County
A6: 606 | B6: Banks County
A7: 607 | B7: Barrow County
A8: 608 | B8: Bartow County
A9: 609 | B9: Ben Hill County
A10: 610 | B10: Berrien County
A11: 611 | B11: Bibb County
A12: 612 | B12: Bleckley County
... A232: 793 | B232: Vidalia City
A233: State Total
